Workbook
Name ´ÑLKOP: #REF!
Name ´ÑLKOP: #REF!
Name ´ÑLKOP: #REF!
Name ´ÑLKOP: #REF!
Name ´ÑLKOP: #REF!
Name ´ÑLKOP: #REF!
Name ´ÑLKOP: #REF!
Name ´ÑPLP: [1]TABLA_VENTAS!$A$3:$D$400
Name Aa: '[2]TABLA-VENTAS'!$A$3:$D$400
Name ABOVELINE: #REF!
Name ABOVELINE: #REF!
Name ABOVELINE: #REF!
Name ABOVELINE: #REF!
Name ABOVELINE: #REF!
Name ABOVELINE: #REF!
Name ABOVELINE: #REF!
Name ADEQ: #REF!
Name ADEQ: #REF!
Name ADEQ: #REF!
Name ADEQ: #REF!
Name ADEQ: #REF!
Name ADEQ: #REF!
Name ADEQ: #REF!
Name adf: '[3]TABLA-VENTAS'!$A$3:$D$400
Name ADQ: [1]TABLA_VENTAS!$A$3:$D$400
Name ADSWWE: '[2]TABLA-VENTAS'!$A$3:$D$400
Name AETA: [1]TABLA_VENTAS!$A$3:$D$400
Name aicnarelot: [4]TABLA_VENTAS!$A$3:$D$400
Name aicnarelot: [5]TABLA_VENTAS!$A$3:$D$400
Name aicnarelot: [6]TABLA_VENTAS!$A$3:$D$400
Name aicnarelot: [7]TABLA_VENTAS!$A$3:$D$400
Name alegriaa: [8]TABLA_VENTAS!$A$3:$D$400
Name alegriaa: [9]TABLA_VENTAS!$A$3:$D$400
Name alegriaa: [10]TABLA_VENTAS!$A$3:$D$400
Name alegriaa: [11]TABLA_VENTAS!$A$3:$D$400
Name ALO: [1]TABLA_VENTAS!$A$3:$D$400
Name AMP: #REF!
Name AMP: #REF!
Name AMP: #REF!
Name AMP: #REF!
Name AMP: #REF!
Name AMP: #REF!
Name AMP: #REF!
Name añq: [1]TABLA_VENTAS!$A$3:$D$400
Name AOL: [1]TABLA_VENTAS!$A$3:$D$400
Name Aqa: #REF!
Name Aqa: #REF!
Name Aqa: #REF!
Name Aqa: #REF!
Name Aqa: #REF!
Name Aqa: #REF!
Name Aqa: #REF!
Name AS: [1]TABLA_VENTAS!$A$3:$D$400
Name ASA: [1]TABLA_VENTAS!$A$3:$D$400
Name ASasSsa: '[3]TABLA-VENTAS'!$A$3:$D$400
Name ASAx: '[3]TABLA-VENTAS'!$A$3:$D$400
Name ASDER: '[2]TABLA-VENTAS'!$A$3:$D$400
Name ased: '[2]TABLA-VENTAS'!$A$3:$D$400
Name ASEDR: '[2]TABLA-VENTAS'!$A$3:$D$400
Name ASEDRF: '[2]TABLA-VENTAS'!$A$3:$D$400

Sheet Cronog Junio 2026
B1: CRONOGRAMA DE MANTENIMIENTO PROGRAMADO JUNIO 2026 | BE1: Plan | BJ1: % completado | BP1: % Completo (más allá del plan)
AW2: Dia | AZ2: 30 | BE2: Real | BJ2: Real (más allá del plan)
B3: SEDES PROGRAMADAS | C3: RESPONSABLE | D3: CENTRO COSTO | E3: UBICACIÓN | F3: ACTIVO FIJO | G3: UES | H3: MODELO | I3: FRECUENCIA | J3: H/H PROGRAMADAS | K3: H/H REALES | L3: DIFERENCIA | M3: FECHA INICIO | N3: FECHA FIN | O3: DURACION DIAS | P3: FECHA REAL DE EJECUCIÓN | Q3: HORAS REALES EJ | R3: TOTAL AUTOGESTIONES | S3: Hidro. Sanit | T3: Tipo | U3: Elect | V3: M2 | W3: O. Civil | X3: M2 | Y3: Apy-Log | Z3: Horas | AA3: Apy-Mtto | AB3: Horas | AC3: Carp. Met | AD3: Tipo | AE3: Chap-Llav | AF3: Tipo | AG3: Carp. Mad | AH3: Tipo | AI3: Pint | AJ3: M2 | AK3: Ad. Ofic | AL3: Tipo | AM3: Cubiert | AN3: M2 | AO3: Señal | AP3: Tipo | AQ3: Pers | AR3: Tipo | AS3: Aut. con Cobro | AT3: Aut. sin Cobro | AU3: PRE VISITA | AV3: % | AW3: 1 Semana | BE3: 2 Semana | BM3: 3 Semana | BT3: 4 Semana
AV4: CUMP | AW4: 1 | AX4: 2 | AY4: 3 | AZ4: 4 | BA4: 5 | BB4: 6 | BC4: 7 | BD4: 8 | BE4: 9 | BF4: 10 | BG4: 11 | BH4: 12 | BI4: 13 | BJ4: 14 | BK4: 15 | BL4: 16 | BM4: 17 | BN4: 18 | BO4: 19 | BP4: 20 | BQ4: 21 | BR4: 22 | BS4: 23 | BT4: 24 | BU4: 25 | BV4: 26 | BW4: 27 | BX4: 28 | BY4: 29 | BZ4: 30 | CA4: 31
AV5: ÍNDICE | AW5: L | AX5: M | AY5: M | AZ5: J | BA5: V | BB5: S | BC5: D | BD5: L | BE5: M | BF5: M | BG5: J | BH5: V | BI5: S | BJ5: D | BK5: L | BL5: M | BM5: M | BN5: J | BO5: V | BP5: S | BQ5: D | BR5: L | BS5: M | BT5: M | BU5: J | BV5: V | BW5: S | BX5: D | BY5: L | BZ5: M | CA5: D
B6: ZONA-NORTE | AU6: =IFERROR(SUMIF(AU7:AU20,"OK",CB7:CB20)/COUNTA(B7:B20),0) -> 0 | AV6: =AVERAGE(AV7:AV31) -> 0.04
A7: 1 | B7: Edificio Comfandi El Prado | C7: Bryan A. Urbano | D7: A010010219 | E7: Cali | F7: 122001186 | G7: ADMINISTRATIVO | H7: In House | I7: Permanente | J7: 307.86 | K7: =+Q7 -> 248.6 | L7: =+K7-J7 -> -59.26 | M7: 1 | N7: 30 | O7: 21 | P7: 1,2,3,4,5,6,9,10,11,12,13,16,17,18,19,20, | Q7: 248.6 | R7: 81 | S7: 5 | T7: 0 | U7: 15 | V7: 0 | W7: 7 | X7: 0 | Y7: 34 | Z7: 0 | AA7: 5 | AB7: 0 | AC7: 4 | AD7: 0 | AE7: 6 | AF7: 0 | AG7: 0 | AH7: 0 | AI7: 2 | AJ7: 0 | AK7: 2 | AL7: 0 | AM7: 0 | AN7: 0 | AO7: 0 | AP7: 0 | AQ7: 1 | AR7: 0 | AS7: 1 | AT7: 80 | AW7: X | AX7: X | AY7: X | AZ7: X | BA7: X | BB7: X | BC7: F | BD7: F | BE7: X | BF7: X | BG7: X | BH7: X | BI7: X | BJ7: F | BK7: F | BL7: X | BM7: X | BN7: X | BO7: X | BP7: X | BQ7: F | BX7: F | BY7: F | CA7: F | CB7: =IF(AU7="OK",1,0) -> 0
A8: 2 | B8: Colegio El Prado Sede Bachillerato | C8: Bryan A. Urbano | D8: E010010205 | E8: Cali | F8: 122001210 | G8: EDUCACION | H8: In House | I8: Permanente | J8: 146.6 | K8: =+Q8 -> 104 | L8: =+K8-J8 -> -42.6 | M8: 1 | N8: 30 | O8: 19 | P8: 1,2,3,4,5,9,10,11,12,16,17,18,19, | Q8: 104 | R8: =+S8+U8+W8+Y8+AC8+AE8+AG8+AI8+AK8+AM8+AO8+AQ8+AA8 -> 119 | S8: 19 | T8: 0 | U8: 6 | V8: 0 | W8: 4 | X8: 0 | Y8: 37 | Z8: 0 | AA8: 36 | AB8: 0 | AC8: 7 | AD8: 0 | AE8: 6 | AF8: 0 | AG8: 0 | AH8: 0 | AI8: 0 | AJ8: 0 | AK8: 0 | AL8: 0 | AM8: 0 | AN8: 0 | AO8: 4 | AP8: 0 | AQ8: 0 | AR8: 0 | AS8: 24 | AT8: 95 | AW8: X | AX8: X | AY8: X | AZ8: X | BA8: X | BC8: F | BD8: F | BE8: X | BF8: X | BG8: X | BH8: X | BJ8: F | BK8: F | BL8: X | BM8: x | BN8: x | BO8: x | BQ8: F | BX8: F | BY8: F | CA8: F | CB8: =IF(AU8="OK",1,0) -> 0
A9: 3 | B9: Ips Comfandi El Prado | C9: Bryan A. Urbano | D9: S010010205 | E9: Cali | F9: 122001312 | G9: SALUD | H9: In House | I9: Permanente | J9: 153.93 | K9: =+Q9 -> 88 | L9: =+K9-J9 -> -65.93 | M9: 1 | N9: 30 | O9: 21 | P9: 1,2,3,4,5,6,9,10,11,12,13,16,17,18,19,20, | Q9: 88 | R9: =+S9+U9+W9+Y9+AC9+AE9+AG9+AI9+AK9+AM9+AO9+AQ9+AA9 -> 64 | S9: 0 | T9: 0 | U9: 0 | V9: 0 | W9: 0 | X9: 0 | Y9: 9 | Z9: 0 | AA9: 51 | AB9: 0 | AC9: 0 | AD9: 0 | AE9: 0 | AF9: 0 | AG9: 0 | AH9: 0 | AI9: 4 | AJ9: 0 | AK9: 0 | AL9: 0 | AM9: 0 | AN9: 0 | AO9: 0 | AP9: 0 | AQ9: 0 | AR9: 0 | AS9: 21 | AT9: 43 | AW9: X | AX9: X | AY9: X | AZ9: X | BA9: X | BB9: X | BC9: F | BD9: F | BJ9: F | BK9: F | BQ9: F | BX9: F | BY9: F | CA9: F | CB9: =IF(AU9="OK",1,0) -> 0
A10: 4 | B10: Centro Campestre Comfandi Arroyohondo | C10: Hans Blake Salas Millan | D10: R010210205 | E10: Yumbo | F10: 122001305 | G10: RECREACION | H10: In House | I10: Permanente | J10: 307.86 | K10: =+Q10 -> 231 | L10: =+K10-J10 -> -76.86 | M10: 1 | N10: 30 | O10: 21 | P10: 1,2,3,4,5,6,9,10,11,12,13,16,17,18,19,20, | Q10: 231 | R10: 70 | S10: 17 | T10: 0 | U10: 10 | V10: 0 | W10: 36 | X10: 0 | Y10: 1 | Z10: 0 | AA10: 0 | AB10: 0 | AC10: 0 | AD10: 0 | AE10: 1 | AF10: 0 | AG10: 0 | AH10: 0 | AI10: 5 | AJ10: 0 | AK10: 0 | AL10: 0 | AM10: 0 | AN10: 0 | AO10: 0 | AP10: 0 | AQ10: 0 | AR10: 0 | AS10: 17 | AT10: 53 | AW10: X | AX10: X | AY10: X | AZ10: X | BA10: X | BB10: X | BC10: F | BD10: F | BE10: X | BF10: X | BG10: X | BH10: X | BI10: X | BJ10: F | BK10: F | BL10: X | BM10: X | BN10: X | BO10: X | BP10: X | BQ10: F | BX10: F | BY10: F | CA10: F | CB10: =IF(AU10="OK",1,0) -> 0
A11: 5 | B11: Colegio Yumbo | C11: Hans Blake Salas Millan | D11: E010030205 | E11: Yumbo | F11: 122001212 | G11: EDUCACION | H11: In House | I11: Permanente | J11: 307.86 | K11: =+Q11 -> 224.6 | L11: =+K11-J11 -> -83.26 | M11: 1 | N11: 30 | O11: 21 | P11: 1,2,3,4,5,9,10,11,12,13,16,17,18,19,20, | Q11: 224.6 | R11: 55 | S11: 7 | T11: 0 | U11: 3 | V11: 0 | W11: 6 | X11: 0 | Y11: 15 | Z11: 0 | AA11: 2 | AB11: 0 | AC11: 5 | AD11: 0 | AE11: 0 | AF11: 0 | AG11: 0 | AH11: 0 | AI11: 4 | AJ11: 0 | AK11: 0 | AL11: 0 | AM11: 12 | AN11: 0 | AO11: 1 | AP11: 0 | AQ11: 0 | AR11: 0 | AS11: 20 | AT11: 35 | AW11: X | AX11: X | AY11: X | AZ11: X | BA11: X | BC11: F | BD11: F | BE11: X | BF11: X | BG11: X | BH11: X | BI11: X | BJ11: F | BK11: F | BL11: X | BM11: X | BN11: X | BO11: X | BP11: X | BQ11: F | BX11: F | BY11: F | CA11: F | CB11: =IF(AU11="OK",1,0) -> 0
A12: 6 | B12: Ips Comfandi Torres | C12: Hans Blake Salas Millan | D12: S010140205 | E12: Cali | F12: 122001317 | G12: SALUD | H12: In House | I12: Permanente | J12: 153.93 | K12: =+Q12 -> 116 | L12: =+K12-J12 -> -37.93 | M12: 1 | N12: 30 | O12: 21 | P12: 1,2,3,4,5,6,9,10,11,12,13,16,17,18,19,20, | Q12: 116 | R12: 84 | S12: 2 | T12: 0 | U12: 3 | V12: 0 | W12: 47 | X12: 0 | Y12: 3 | Z12: 0 | AA12: 23 | AB12: 0 | AC12: 0 | AD12: 0 | AE12: 1 | AF12: 0 | AG12: 0 | AH12: 0 | AI12: 5 | AJ12: 0 | AK12: 0 | AL12: 0 | AM12: 0 | AN12: 0 | AO12: 0 | AP12: 0 | AQ12: 0 | AR12: 0 | AS12: 35 | AT12: 49 | AW12: X | AX12: X | AY12: X | AZ12: X | BA12: X | BB12: X | BC12: F | BD12: F | BE12: X | BF12: X | BG12: X | BH12: X | BI12: X | BJ12: F | BK12: F | BL12: X | BM12: X | BN12: X | BO12: X | BP12: X | BQ12: F | BX12: F | BY12: F | CA12: F | CB12: =IF(AU12="OK",1,0) -> 0
A13: 7 | B13: Drogueria Av. 6 La Flora 2 | C13: Hans Blake Salas Millan | D13: M012070213 | E13: Cali | F13: 122001279 | G13: MERCADEO | H13: Móvil | I13: Bimestral | J13: 8 | K13: =+Q13 -> 0 | L13: =+K13-J13 -> -8 | M13: 24 | N13: 24 | O13: 0.54570259 | R13: =+S13+U13+W13+Y13+AC13+AE13+AG13+AI13+AK13+AM13+AO13+AQ13+AA13 -> 0 | BC13: F | BD13: F | BJ13: F | BK13: F | BQ13: F | BX13: F | BY13: F | CA13: F | CB13: =IF(AU13="OK",1,0) -> 0
A14: 8 | B14: Drogueria Av. Sexta | C14: Hans Blake Salas Millan | D14: M010360213 | E14: Cali | F14: 122001232 | G14: MERCADEO | H14: Móvil | I14: Bimestral | J14: 8 | K14: =+Q14 -> 0 | L14: =+K14-J14 -> -8 | M14: 27 | N14: 27 | O14: 0.54570259 | R14: =+S14+U14+W14+Y14+AC14+AE14+AG14+AI14+AK14+AM14+AO14+AQ14+AA14 -> 0 | BC14: F | BD14: F | BJ14: F | BK14: F | BQ14: F | BX14: F | BY14: F | CA14: F | CB14: =IF(AU14="OK",1,0) -> 0
A15: 9 | B15: Droguería Centenario | C15: Bryan A. Urbano | D15: M011410213 | E15: Cali | F15: 122001250 | G15: MERCADEO | H15: Móvil | I15: Bimestral | J15: 8 | K15: =+Q15 -> 0 | L15: =+K15-J15 -> -8 | M15: 30 | N15: 30 | O15: 0.54570259 | R15: =+S15+U15+W15+Y15+AC15+AE15+AG15+AI15+AK15+AM15+AO15+AQ15+AA15 -> 0 | BC15: F | BD15: F | BJ15: F | BK15: F | BQ15: F | BX15: F | BY15: F | CA15: F | CB15: =IF(AU15="OK",1,0) -> 0
A16: 10 | B16: Drogueria Chipichape | C16: Hans Blake Salas Millan | D16: M011680213 | E16: Cali | F16: 122001269 | G16: MERCADEO | H16: Móvil | I16: Bimestral | J16: 8 | K16: =+Q16 -> 0 | L16: =+K16-J16 -> -8 | M16: 27 | N16: 27 | O16: 0.54570259 | R16: =+S16+U16+W16+Y16+AC16+AE16+AG16+AI16+AK16+AM16+AO16+AQ16+AA16 -> 0 | BC16: F | BD16: F | BJ16: F | BK16: F | BQ16: F | BX16: F | BY16: F | CA16: F
A17: 11 | B17: Drogueria Clinica de Occidente | C17: Bryan A. Urbano | D17: M011930213 | E17: Cali | F17: 122001275 | G17: MERCADEO | H17: Móvil | I17: Bimestral | J17: 8 | K17: =+Q17 -> 0 | L17: =+K17-J17 -> -8 | M17: 25 | N17: 25 | O17: 0.54570259 | R17: =+S17+U17+W17+Y17+AC17+AE17+AG17+AI17+AK17+AM17+AO17+AQ17+AA17 -> 0 | BC17: F | BD17: F | BJ17: F | BK17: F | BQ17: F | BX17: F | BY17: F | CA17: F | CB17: =IF(AU17="OK",1,0) -> 0
A18: 12 | B18: Drogueria Clinica Remedios | C18: Bryan A. Urbano | D18: M010410213 | E18: Cali | F18: 122001233 | G18: MERCADEO | H18: Móvil | I18: Bimestral | J18: 8 | K18: =+Q18 -> 0 | L18: =+K18-J18 -> -8 | M18: 26 | N18: 26 | O18: 0.54570259 | R18: =+S18+U18+W18+Y18+AC18+AE18+AG18+AI18+AK18+AM18+AO18+AQ18+AA18 -> 0 | BC18: F | BD18: F | BJ18: F | BK18: F | BQ18: F | BX18: F | BY18: F | CA18: F | CB18: =IF(AU18="OK",1,0) -> 0
A19: 13 | B19: Drogueria El Prado | C19: Bryan A. Urbano | D19: M010321701 | E19: Cali | F19: 122001260 | G19: MERCADEO | H19: Móvil | I19: Bimestral | J19: 8 | K19: =+Q19 -> 0 | L19: =+K19-J19 -> -8 | M19: 30 | N19: 30 | O19: 0.54570259 | R19: =+S19+U19+W19+Y19+AC19+AE19+AG19+AI19+AK19+AM19+AO19+AQ19+AA19 -> 0 | BC19: F | BD19: F | BJ19: F | BK19: F | BQ19: F | BX19: F | BY19: F | CA19: F | CB19: =IF(AU19="OK",1,0) -> 0
A20: 14 | B20: Drogueria La Flora | C20: Hans Blake Salas Millan | D20: M011080213 | E20: Cali | F20: 122001237 | G20: MERCADEO | H20: Móvil | I20: Bimestral | J20: 8 | K20: =+Q20 -> 0 | L20: =+K20-J20 -> -8 | M20: 24 | N20: 24 | O20: 0.54570259 | R20: =+S20+U20+W20+Y20+AC20+AE20+AG20+AI20+AK20+AM20+AO20+AQ20+AA20 -> 0 | BC20: F | BD20: F | BJ20: F | BK20: F | BQ20: F | BX20: F | BY20: F | CA20: F | CB20: =IF(AU20="OK",1,0) -> 0
A21: 15 | B21: Ips Comfandi Yumbo | C21: Hans Blake Salas Millan | D21: S010030205 | E21: Yumbo | F21: 122001313 | G21: SALUD | H21: Móvil | I21: Mensual | J21: 124 | K21: =+Q21 -> 136 | L21: =+K21-J21 -> 12 | M21: 1 | N21: 11 | O21: 8.4583902 | P21: 1,2,3,4,5,6,9,10,11, | Q21: 136 | R21: =+S21+U21+W21+Y21+AC21+AE21+AG21+AI21+AK21+AM21+AO21+AQ21+AA21 -> 38 | S21: 5 | T21: 0 | U21: 6 | V21: 0 | W21: 9 | X21: 0 | Y21: 1 | Z21: 0 | AA21: 0 | AB21: 0 | AC21: 4 | AD21: 0 | AE21: 1 | AF21: 0 | AG21: 1 | AH21: 0 | AI21: 11 | AJ21: 0 | AK21: 0 | AL21: 0 | AM21: 0 | AN21: 0 | AO21: 0 | AP21: 0 | AQ21: 0 | AR21: 0 | AS21: 23 | AT21: 15 | AV21: 0.04 | AW21: X | AX21: X | AY21: X | AZ21: X | BA21: X | BB21: X | BC21: F | BD21: F | BE21: X | BF21: X | BG21: X | BJ21: F | BK21: F | BQ21: F | BX21: F | BY21: F | CA21: F
A22: 16 | B22: Colegio Municipal | C22: Bryan A. Urbano | D22: E010600205 | E22: Cali | F22: 122001217 | G22: EDUCACION | H22: Móvil | I22: Mensual | J22: 88 | K22: =+Q22 -> 96 | L22: =+K22-J22 -> 8 | M22: 12 | N22: 20 | O22: 6.0027285 | P22: 12,13,16,17,18,19,20, | Q22: 96 | R22: 30 | S22: 3 | T22: 0 | U22: 8 | V22: 0 | W22: 6 | X22: 0 | Y22: 2 | Z22: 0 | AA22: 1 | AB22: 0 | AC22: 5 | AD22: 0 | AE22: 0 | AF22: 0 | AG22: 1 | AH22: 0 | AI22: 2 | AJ22: 0 | AK22: 0 | AL22: 0 | AM22: 1 | AN22: 0 | AO22: 1 | AP22: 0 | AQ22: 0 | AR22: 0 | AS22: 19 | AT22: 11 | BC22: F | BD22: F | BH22: X | BI22: X | BJ22: F | BK22: F | BL22: X | BM22: X | BN22: X | BO22: X | BP22: X | BQ22: F | BX22: F | BY22: F | CA22: F | CB22: =IF(AU22="OK",1,0) -> 0
A23: 17 | B23: Colegio Las Delicias | C23: Bryan A. Urbano | D23: E010190205 | E23: Cali | F23: 122001215 | G23: EDUCACION | H23: Móvil | I23: Mensual | J23: 74 | K23: =+Q23 -> 0 | L23: =+K23-J23 -> -74 | M23: 22 | N23: 26 | O23: 5.047749 | R23: =+S23+U23+W23+Y23+AC23+AE23+AG23+AI23+AK23+AM23+AO23+AQ23+AA23 -> 0 | BC23: F | BD23: F | BJ23: F | BK23: F | BQ23: F | BX23: F | BY23: F | CA23: F | CB23: =IF(AU23="OK",1,0) -> 0
A24: 18 | B24: Ips Comfandi Alameda | C24: Bryan A. Urbano | D24: S010080205 | E24: Cali | F24: 122001314 | G24: SALUD | H24: Móvil | I24: Mensual | J24: 124 | K24: =+Q24 -> 136 | L24: =+K24-J24 -> 12 | M24: 1 | N24: 11 | O24: 8.4583902 | P24: 1,2,3,4,5,6,9,10,11, | Q24: 136 | R24: =+S24+U24+W24+Y24+AC24+AE24+AG24+AI24+AK24+AM24+AO24+AQ24+AA24 -> 48 | S24: 11 | T24: 0 | U24: 8 | V24: 0 | W24: 6 | X24: 0 | Y24: 3 | Z24: 0 | AA24: 1 | AB24: 0 | AC24: 5 | AD24: 0 | AE24: 1 | AF24: 0 | AG24: 2 | AH24: 0 | AI24: 6 | AJ24: 0 | AK24: 0 | AL24: 0 | AM24: 2 | AN24: 0 | AO24: 3 | AP24: 0 | AQ24: 0 | AR24: 0 | AS24: 13 | AT24: 35 | AW24: X | AX24: X | AY24: X | AZ24: X | BA24: X | BB24: X | BC24: F | BD24: F | BE24: X | BF24: X | BG24: X | BJ24: F | BK24: F | BQ24: F | BX24: F | BY24: F | CA24: F | CB24: =IF(AU24="OK",1,0) -> 0
A25: 19 | B25: Colegio Miraflores Sede Bachillerato | C25: Bryan A. Urbano | D25: E010620205 | E25: Cali | F25: 122001218 | G25: EDUCACION | H25: Móvil | I25: Mensual | J25: 118 | K25: =+Q25 -> 0 | L25: =+K25-J25 -> -118 | M25: 12 | N25: 23 | O25: 8.0491132 | P25: 12,13,16,17,18,19,20,22,23,24,25, | R25: =+S25+U25+W25+Y25+AC25+AE25+AG25+AI25+AK25+AM25+AO25+AQ25+AA25 -> 0 | BC25: F | BD25: F | BH25: X | BI25: X | BJ25: F | BK25: F | BL25: X | BM25: X | BN25: X | BO25: X | BP25: X | BQ25: F | BR25: X | BS25: X | BT25: X | BU25: X | BX25: F | BY25: F | CA25: F | CB25: =IF(AU25="OK",1,0) -> 0
A26: 20 | B26: Campus E Centro | C26: Bryan A. Urbano | D26: E010050205 | E26: Cali | F26: 122001220 | G26: EDUCACION | H26: Móvil | I26: Mensual | J26: 124 | K26: =+Q26 -> 136 | L26: =+K26-J26 -> 12 | M26: 1 | N26: 11 | O26: 8.4583902 | P26: 1,2,3,4,5,6,9,10,11, | Q26: 136 | R26: =+S26+U26+W26+Y26+AC26+AE26+AG26+AI26+AK26+AM26+AO26+AQ26+AA26 -> 39 | S26: 8 | T26: 0 | U26: 8 | V26: 0 | W26: 5 | X26: 0 | Y26: 6 | Z26: 0 | AA26: 2 | AB26: 0 | AC26: 4 | AD26: 0 | AE26: 1 | AF26: 0 | AG26: 1 | AH26: 0 | AI26: 3 | AJ26: 0 | AK26: 0 | AL26: 0 | AM26: 1 | AN26: 0 | AO26: 0 | AP26: 0 | AQ26: 0 | AR26: 0 | AS26: 16 | AT26: 23 | AW26: X | AX26: X | AY26: X | AZ26: X | BA26: X | BB26: X | BC26: F | BD26: F | BE26: X | BF26: X | BG26: X | BJ26: F | BK26: F | BQ26: F | BX26: F | BY26: F | CA26: F | CB26: =IF(AU26="OK",1,0) -> 0
A27: 21 | B27: Campus E Centro (Fomento Piso 3) | C27: Bryan A. Urbano | D27: E010050205 | E27: Cali | F27: 122001220 | G27: EDUCACION | H27: Móvil | I27: Mensual | J27: 22 | K27: =+Q27 -> 24 | L27: =+K27-J27 -> 2 | M27: 12 | N27: 13 | O27: 1.5006821 | P27: 12;13, | Q27: 24 | R27: =+S27+U27+W27+Y27+AC27+AE27+AG27+AI27+AK27+AM27+AO27+AQ27+AA27 -> 5 | S27: 0 | T27: 0 | U27: 0 | V27: 0 | W27: 0 | X27: 0 | Y27: 0 | Z27: 0 | AA27: 1 | AB27: 0 | AC27: 0 | AD27: 0 | AE27: 1 | AF27: 0 | AG27: 0 | AH27: 0 | AI27: 3 | AJ27: 0 | AK27: 0 | AL27: 0 | AM27: 0 | AN27: 0 | AO27: 0 | AP27: 0 | AQ27: 0 | AR27: 0 | AS27: 4 | AT27: 1 | BC27: F | BD27: F | BH27: X | BI27: X | BJ27: F | BK27: F | BQ27: F | BX27: F | BY27: F | CA27: F | CB27: =IF(AU27="OK",1,0) -> 0
A28: 22 | B28: Colegio Calipso | C28: Bryan A. Urbano | D28: E010020205 | E28: Cali | F28: 122001211 | G28: EDUCACION | H28: Móvil | I28: Mensual | J28: 96 | K28: =+Q28 -> 88 | L28: =+K28-J28 -> -8 | M28: 16 | N28: 23 | O28: 6.5484311 | P28: 16,17,18,19,20,22 | Q28: 88 | R28: 29 | BC28: F | BD28: F | BJ28: F | BK28: F | BL28: X | BM28: X | BN28: X | BO28: X | BP28: X | BQ28: F | BR28: X | BX28: F | BY28: F | CA28: F | CB28: =IF(AU28="OK",1,0) -> 0
A29: 23 | B29: Colegio San Nicolas - Biblioteca - Auditorio | C29: Bryan A. Urbano | D29: E010040205 | E29: Cali | F29: 122001213 | G29: EDUCACION | H29: Móvil | I29: Mensual | J29: 124 | K29: =+Q29 -> 136 | L29: =+K29-J29 -> 12 | M29: 1 | N29: 11 | O29: 8.4583902 | P29: 1,2,3,4,5,6,9,10,11, | Q29: 136 | R29: =+S29+U29+W29+Y29+AC29+AE29+AG29+AI29+AK29+AM29+AO29+AQ29+AA29 -> 55 | S29: 6 | T29: 0 | U29: 4 | V29: 0 | W29: 4 | X29: 0 | Y29: 3 | Z29: 0 | AA29: 0 | AB29: 0 | AC29: 9 | AD29: 0 | AE29: 3 | AF29: 0 | AG29: 8 | AH29: 0 | AI29: 5 | AJ29: 0 | AK29: 3 | AL29: 0 | AM29: 8 | AN29: 0 | AO29: 2 | AP29: 0 | AQ29: 0 | AR29: 0 | AS29: 25 | AT29: 30 | AW29: X | AX29: X | AY29: X | AZ29: X | BA29: X | BB29: X | BC29: F | BD29: F | BE29: X | BF29: X | BG29: X | BJ29: F | BK29: F | BQ29: F | BX29: F | BY29: F | CA29: F | CB29: =IF(AU29="OK",1,0) -> 0
A30: 24 | B30: Ips Comfandi San Nicolas | C30: Bryan A. Urbano | D30: S010160205 | E30: Cali | F30: 122001318 | G30: SALUD | H30: Móvil | I30: Mensual | J30: 52 | K30: =+Q30 -> 0 | L30: =+K30-J30 -> -52 | M30: 25 | N30: 30 | O30: 3.5470668 | R30: =+S30+U30+W30+Y30+AC30+AE30+AG30+AI30+AK30+AM30+AO30+AQ30+AA30 -> 0 | BC30: F | BD30: F | BJ30: F | BK30: F | BQ30: F | BX30: F | BY30: F | CA30: F | CB30: =IF(AU30="OK",1,0) -> 0
A31: 25 | B31: IETDH San Nicolas | C31: Bryan A. Urbano | D31: E010046105 | E31: Cali | F31: 122001227 | G31: EDUCACION | H31: Móvil | I31: Mensual | J31: 132 | K31: =+Q31 -> 144 | L31: =+K31-J31 -> 12 | M31: 12 | N31: 24 | O31: 9.0040928 | P31: 12,13,16,17,18,19,20,22,23,24, | Q31: 144 | R31: 58 | S31: 7 | T31: 0 | U31: 17 | V31: 0 | W31: 12 | X31: 0 | Y31: 0 | Z31: 0 | AA31: 1 | AB31: 0 | AC31: 5 | AD31: 0 | AE31: 4 | AF31: 0 | AG31: 2 | AH31: 0 | AI31: 3 | AJ31: 0 | AK31: 0 | AL31: 0 | AM31: 6 | AN31: 0 | AO31: 1 | AP31: 0 | AQ31: 0 | AR31: 0 | AS31: 27 | AT31: 31 | BC31: F | BD31: F | BH31: X | BI31: X | BJ31: F | BK31: F | BL31: X | BM31: X | BN31: X | BO31: X | BP31: X | BQ31: F | BR31: X | BS31: X | BT31: X | BX31: F | BY31: F | CA31: F | CB31: =IF(AU31="OK",1,0) -> 0
A32: 26 | B32: Colegio El Prado Sede Bachillerato (Móvil) | C32: Bryan A. Urbano | D32: E010010205 | E32: Cali | F32: 122001210 | G32: EDUCACION | H32: Móvil | I32: Mensual | J32: 66 | K32: =+Q32 -> 0 | L32: =+K32-J32 -> -66 | M32: 24 | N32: 30 | O32: 4.5020464 | R32: =+S32+U32+W32+Y32+AC32+AE32+AG32+AI32+AK32+AM32+AO32+AQ32+AA32 -> 0 | BC32: F | BD32: F | BJ32: F | BK32: F | BQ32: F | BX32: F | BY32: F
B33: ZONA-SUR | AU33: =IFERROR(SUMIF(AU34:AU54,"OK",CB34:CB54)/COUNTA(B34:B54),0) -> 0 | AV33: =AVERAGE(AV34:AV44) -> 0.04 | CB33: =IF(AU33="OK",1,0) -> 0
A34: 1 | B34: Centro Campestre Comfandi Pance | C34: Andres Carrillo | D34: R010250205 | E34: Cali | F34: 122001306 | G34: RECREACION | H34: In House | I34: Permanente | J34: 615.72 | K34: =+Q34 -> 496 | L34: =+K34-J34 -> -119.72 | M34: 1 | N34: 30 | O34: 21 | P34: 1,2,3,4,5,6,9,10,11,12,13,16,17,18,19,20, | Q34: 496 | R34: 57 | S34: 7 | T34: 0 | U34: 15 | V34: 0 | W34: 15 | X34: 0 | Y34: 8 | Z34: 0 | AA34: 1 | AB34: 0 | AC34: 7 | AD34: 0 | AE34: 0 | AF34: 0 | AG34: 0 | AH34: 0 | AI34: 2 | AJ34: 0 | AK34: 1 | AL34: 0 | AM34: 1 | AN34: 0 | AO34: 0 | AP34: 0 | AQ34: 0 | AR34: 0 | AS34: 43 | AT34: 14 | AW34: X | AX34: X | AY34: X | AZ34: X | BA34: X | BB34: X | BC34: F | BD34: F | BE34: X | BF34: X | BG34: X | BH34: X | BI34: X | BJ34: F | BK34: F | BL34: X | BM34: X | BN34: X | BO34: X | BP34: X | BQ34: F | BX34: F | BY34: F | CA34: F | CB34: =IF(AU34="OK",1,0) -> 0
A35: 2 | B35: Clinica Comfandi Tequendama | C35: Andres Carrillo | D35: S010120205 | E35: Cali | F35: 122001316 | G35: SALUD | H35: In House | I35: Permanente | J35: 461.79 | K35: =+Q35 -> 391.8 | L35: =+K35-J35 -> -69.99 | M35: 1 | N35: 30 | O35: 21 | P35: 1,2,3,4,5,6,9,10,11,12,13,165,17,18,19,20, | Q35: 391.8 | R35: 84 | S35: 4 | T35: 0 | U35: 11 | V35: 0 | W35: 6 | X35: 0 | Y35: 25 | Z35: 0 | AA35: 27 | AB35: 0 | AC35: 1 | AD35: 0 | AE35: 3 | AF35: 0 | AG35: 0 | AH35: 0 | AI35: 3 | AJ35: 0 | AK35: 2 | AL35: 0 | AM35: 0 | AN35: 0 | AO35: 2 | AP35: 0 | AQ35: 0 | AR35: 0 | AS35: 23 | AT35: 61 | AV35: 0.04 | AW35: X | AX35: X | AY35: X | AZ35: X | BA35: X | BB35: X | BC35: F | BD35: F | BE35: X | BF35: X | BG35: X | BH35: X | BI35: X | BJ35: F | BK35: F | BL35: X | BM35: X | BN35: X | BO35: X | BP35: X | BQ35: F | BX35: F | BY35: F | CA35: F | CB35: =IF(AU35="OK",1,0) -> 0
A36: 3 | B36: Laboratorio Especializado | C36: Andres Carrillo | D36: S010160205 | E36: Cali | F36: 122001318 | G36: SALUD | H36: Móvil | I36: Mensual | J36: 44 | K36: =+Q36 -> 40 | L36: =+K36-J36 -> -4 | M36: 18 | N36: 20 | O36: 3.0013643 | P36: 18,19,20, | Q36: 40 | R36: 14 | S36: 1 | T36: 0 | U36: 1 | V36: 0 | W36: 1 | X36: 0 | Y36: 2 | Z36: 0 | AA36: 0 | AB36: 0 | AC36: 0 | AD36: 0 | AE36: 2 | AF36: 0 | AG36: 0 | AH36: 0 | AI36: 7 | AJ36: 0 | AK36: 0 | AL36: 0 | AM36: 0 | AN36: 0 | AO36: 0 | AP36: 0 | AQ36: 0 | AR36: 0 | AS36: 7 | AT36: 7 | BC36: F | BD36: F | BJ36: F | BK36: F | BN36: X | BO36: X | BP36: X | BQ36: F | BX36: F | BY36: F | CA36: F | CB36: =IF(AU36="OK",1,0) -> 0
A37: 4 | B37: Drogueria Cañas Gordas | C37: Andres Carrillo | D37: M011501701 | E37: Cali | F37: 122001264 | G37: MERCADEO | H37: Móvil | I37: Bimestral | J37: 14 | K37: =+Q37 -> 16 | L37: =+K37-J37 -> 2 | M37: 4 | N37: 4 | O37: 0.95497954 | P37: 4 | Q37: 16 | R37: =+S37+U37+W37+Y37+AC37+AE37+AG37+AI37+AK37+AM37+AO37+AQ37+AA37 -> 10 | S37: 2 | T37: 0 | U37: 2 | V37: 0 | W37: 2 | X37: 0 | Y37: 0 | Z37: 0 | AA37: 0 | AB37: 0 | AC37: 0 | AD37: 0 | AE37: 3 | AF37: 0 | AG37: 1 | AH37: 0 | AI37: 0 | AJ37: 0 | AK37: 0 | AL37: 0 | AM37: 0 | AN37: 0 | AO37: 0 | AP37: 0 | AQ37: 0 | AR37: 0 | AS37: 6 | AT37: 4 | AZ37: X | BC37: F | BD37: F | BJ37: F | BK37: F | BQ37: F | BX37: F | BY37: F | CA37: F | CB37: =IF(AU37="OK",1,0) -> 0
A38: 5 | B38: Droguería Cañaveralejo | C38: Andres Carrillo | D38: M011360213 | E38: Cali | F38: 122001245 | G38: MERCADEO | H38: Móvil | I38: Bimestral | J38: 14 | K38: =+Q38 -> 16 | L38: =+K38-J38 -> 2 | M38: 16 | N38: 16 | O38: 0.95497954 | P38: 16 | Q38: 16 | R38: =+S38+U38+W38+Y38+AC38+AE38+AG38+AI38+AK38+AM38+AO38+AQ38+AA38 -> 11 | S38: 1 | T38: 0 | U38: 2 | V38: 0 | W38: 1 | X38: 0 | Y38: 0 | Z38: 0 | AA38: 0 | AB38: 0 | AC38: 0 | AD38: 0 | AE38: 2 | AF38: 0 | AG38: 4 | AH38: 0 | AI38: 1 | AJ38: 0 | AK38: 0 | AL38: 0 | AM38: 0 | AN38: 0 | AO38: 0 | AP38: 0 | AQ38: 0 | AR38: 0 | AS38: 8 | AT38: 3 | BC38: F | BD38: F | BJ38: F | BK38: F | BL38: X | BQ38: F | BX38: F | BY38: F | CA38: F | CB38: =IF(AU38="OK",1,0) -> 0
A39: 6 | B39: Drogueria Cerros Plaza | C39: Andres Carrillo | D39: M011610213 | E39: Cali | F39: 122001267 | G39: MERCADEO | H39: Móvil | I39: Bimestral | J39: 14 | K39: =+Q39 -> 24 | L39: =+K39-J39 -> 10 | M39: 5 | N39: 5 | O39: 0.95497954 | P39: 5 | Q39: 24 | R39: =+S39+U39+W39+Y39+AC39+AE39+AG39+AI39+AK39+AM39+AO39+AQ39+AA39 -> 10 | S39: 1 | T39: 0 | U39: 3 | V39: 0 | W39: 2 | X39: 0 | Y39: 0 | Z39: 0 | AA39: 0 | AB39: 0 | AC39: 0 | AD39: 0 | AE39: 2 | AF39: 0 | AG39: 0 | AH39: 0 | AI39: 2 | AJ39: 0 | AK39: 0 | AL39: 0 | AM39: 0 | AN39: 0 | AO39: 0 | AP39: 0 | AQ39: 0 | AR39: 0 | AS39: 7 | AT39: 3 | BA39: X | BC39: F | BD39: F | BJ39: F | BK39: F | BQ39: F | BX39: F | BY39: F | CA39: F
A40: 7 | B40: Drogueria Clinica Vida | C40: Andres Carrillo | D40: M012220213 | E40: Cali | F40: 122001276 | G40: MERCADEO | H40: Móvil | I40: Bimestral | J40: 14 | K40: =+Q40 -> 16 | L40: =+K40-J40 -> 2 | M40: 17 | N40: 17 | O40: 0.95497954 | P40: 19 | Q40: 16 | R40: =+S40+U40+W40+Y40+AC40+AE40+AG40+AI40+AK40+AM40+AO40+AQ40+AA40 -> 7 | S40: 1 | T40: 0 | U40: 1 | V40: 0 | W40: 1 | X40: 0 | Y40: 0 | Z40: 0 | AA40: 0 | AB40: 0 | AC40: 0 | AD40: 0 | AE40: 2 | AF40: 0 | AG40: 2 | AH40: 0 | AI40: 0 | AJ40: 0 | AK40: 0 | AL40: 0 | AM40: 0 | AN40: 0 | AO40: 0 | AP40: 0 | AQ40: 0 | AR40: 0 | AS40: 5 | AT40: 2 | BC40: F | BD40: F | BJ40: F | BK40: F | BO40: X | BQ40: F | BX40: F | BY40: F | CA40: F
...

Sheet Hoja1
A1: ITEM | B1: SEDE COMFANDI | C1: CECOS | D1: ACTIVO FIJO | E1: UES | F1: ZONA | G1: CIUDAD | H1: MODELO | I1: SUPERVISOR
A2: 1 | B2: Agencia de Gestión y Colocación de Empleo Buenaventura | C2: ORD500782 | D2: 122001327 | E2: FOMENTO | F2: VALLE1 | G2: Buenaventura | H2: In House | I2: Sebastian andres padilla
A3: 2 | B3: Agencia de Gestión y Colocación de Empleo Buga | C3: ORD500782 | D3: 122001328 | E3: FOMENTO | F3: VALLE1 | G3: Buga | H3: Movil | I3: Sebastian andres padilla
A4: 3 | B4: Agencia de Gestión y Colocación de Empleo Palmira | C4: ORD500782 | D4: 122001326 | E4: FOMENTO | F4: NORTE | G4: Palmira | H4: Movil | I4: Hans Blake Salas Millan
A5: 4 | B5: Agencia de Gestión y Colocación de Empleo Tuluá | C5: ORD500782 | D5: 122001329 | E5: FOMENTO | F5: VALLE1 | G5: Tuluá | H5: Movil | I5: Sebastian andres padilla
A6: 5 | B6: Biblioteca Buga Adultos FTDH | C6: E030026005 | D6: 122001228 | E6: EDUCACIÓN | F6: VALLE1 | G6: Buga | H6: Movil | I6: Sebastian andres padilla
A7: 6 | B7: Biblioteca Central Palmira | C7: E020010205 | D7: 122001221 | E7: EDUCACIÓN | F7: NORTE | G7: Palmira | H7: Movil | I7: Hans Blake Salas Millan
A8: 7 | B8: Biblioteca escolar colegio palmira | C8: E020010205 | D8: 122001221 | E8: EDUCACIÓN | F8: NORTE | G8: Palmira | H8: Movil | I8: Hans Blake Salas Millan
A9: 8 | B9: Biblioteca Florida | C9: E020010205 | D9: 122001221 | E9: EDUCACIÓN | F9: NORTE | G9: Florida | H9: Movil | I9: Hans Blake Salas Millan
A10: 9 | B10: Biblioteca Pública Escolar El Cerrito | C10: E020040801 | D10: 122001225 | E10: EDUCACIÓN | F10: NORTE | G10: El Cerrito | H10: Movil | I10: Hans Blake Salas Millan
A11: 10 | B11: Biblioteca Pública Escolar San Antonio de los Caballeros | C11: E020390801 | D11: 122001226 | E11: EDUCACIÓN | F11: NORTE | G11: Florida | H11: Movil | I11: Hans Blake Salas Millan
A12: 11 | B12: Centro Campestre Comfandi Arroyohondo | C12: R010210205 | D12: 122001305 | E12: RECREACIÓN | F12: NORTE | G12: Yumbo | H12: In House | I12: Hans Blake Salas Millan
A13: 12 | B13: Centro Campestre Comfandi Pance | C13: R010250205 | D13: 122001306 | E13: RECREACIÓN | F13: SUR | G13: Cali | H13: In House | I13: Andres Carrillo
... A118: 117 | B118: Colegio El Prado Sede Bachillerato (Móvil) | C118: E010010205 | D118: 122001210 | E118: EDUCACIÓN | F118: CENTRO | G118: Cali | H118: Movil | I118: Bryan A. Urbano

Sheet Entregas
A2: ENTREGA DIARIA CHECK LIST MANTENIMIENTO PROGRAMADO
B3: DATOS GENERALES | H3: CANTIDAD AUTOGESTIONES-PILARES DE MANTENIMIENTO | AH3: TIPO AUTOGESTIÓN
A5: SEDE | B5: SUPERVISOR | C5: UES | D5: C. COSTO | E5: FECHAS DE EJECUCIÓN | F5: HORAS EJECUTADAS | G5: CANTIDAD AUTOGESTIONES | H5: HID-SAN | I5: Tipo | J5: INS-ELE | K5: M2 | L5: OBR-CIV | M5: M22 | N5: APY-LOG | O5: Horas | P5: APY-MTTO | Q5: Horas | R5: CARP-MET | S5: Tipo3 | T5: CHA-LLAV | U5: Tipo4 | V5: CARP-MAD | W5: Tipo5 | X5: PINT | Y5: M26 | Z5: ADE-OFI | AA5: Tipo7 | AB5: CUBI | AC5: M28 | AD5: SEÑA | AE5: Tipo9 | AF5: PERSIA | AG5: Tipo10 | AH5: CON COBRO | AI5: SIN COBRO | AJ5: N° CHECK LIST | AK5: facilitador | AL5: INDICE | AM5: DRIVE | AN5: GESTOR RESPONSABLE
A6: Edificio Comfandi El Prado | B6: =VLOOKUP(Tabla6[[#This Row],[SEDE]],'Cronog Junio 2026'!B3:C94,2,0) -> Bryan A. Urbano | C6: =VLOOKUP(Tabla6[[#This Row],[SEDE]],'Cronog Junio 2026'!B3:G94,6,0) -> ADMINISTRATIVO | D6: =VLOOKUP(Tabla6[[#This Row],[SEDE]],'Cronog Junio 2026'!B3:D94,3,0) -> A010010219 | E6: 1,2,3,4,5,6, | F6: 93.6 | G6: =+H6+J6+L6+N6+P6+R6+T6+V6+X6+Z6+AB6+AD6+AF6 -> 32 | H6: 1 | I6: 0 | J6: 7 | K6: 0 | L6: 5 | M6: 0 | N6: 12 | O6: 0 | P6: 3 | Q6: 0 | R6: 1 | S6: 0 | T6: 2 | U6: 0 | V6: 0 | W6: 0 | X6: 0 | Y6: 0 | Z6: 0 | AA6: 0 | AB6: 0 | AC6: 0 | AD6: 0 | AE6: 0 | AF6: 1 | AG6: 0 | AH6: 0 | AI6: 32 | AJ6: 5049-5058-5060-5061-5062-5071 | AK6: por firma de gestor | AL6: NO | AM6: OK | AN6: DIANA RAMOS/JOAQUIN DELGADO
E7: 9,10,11,12,13, | F7: 72 | G7: =+H7+J7+L7+N7+P7+R7+T7+V7+X7+Z7+AB7+AD7+AF7 -> 22 | H7: 2 | I7: 0 | J7: 3 | K7: 0 | L7: 2 | M7: 0 | N7: 9 | O7: 0 | P7: 1 | Q7: 0 | R7: 1 | S7: 0 | T7: 2 | U7: 0 | V7: 0 | W7: 0 | X7: 0 | Y7: 0 | Z7: 2 | AA7: 0 | AB7: 0 | AC7: 0 | AD7: 0 | AE7: 0 | AF7: 0 | AG7: 0 | AH7: 1 | AI7: 21 | AJ7: 5193-5194-5195-5196-5198 | AK7: por firma de gestor | AL7: NO | AM7: OK
E8: 16,17,18,19,20 | F8: 83 | G8: =+H8+J8+L8+N8+P8+R8+T8+V8+X8+Z8+AB8+AD8+AF8 -> 27 | H8: 2 | I8: 0 | J8: 5 | K8: 0 | L8: 0 | M8: 0 | N8: 13 | O8: 0 | P8: 1 | Q8: 0 | R8: 2 | S8: 0 | T8: 2 | U8: 0 | V8: 0 | W8: 0 | X8: 2 | Y8: 0 | Z8: 0 | AA8: 0 | AB8: 0 | AC8: 0 | AD8: 0 | AE8: 0 | AF8: 0 | AG8: 0 | AH8: 0 | AI8: 27 | AJ8: 5301-5304-5322-5311-5312 | AK8: por firma de gestor | AL8: NO | AM8: OK
A10: Colegio El Prado Sede Bachillerato | B10: =VLOOKUP(Tabla6[[#This Row],[SEDE]],'Cronog Junio 2026'!B4:C95,2,0) -> Bryan A. Urbano | C10: =VLOOKUP(Tabla6[[#This Row],[SEDE]],'Cronog Junio 2026'!B4:G95,6,0) -> EDUCACION | D10: =VLOOKUP(Tabla6[[#This Row],[SEDE]],'Cronog Junio 2026'!B4:D95,3,0) -> E010010205 | E10: 1,2,3,4,5, | F10: 40 | G10: =+H10+J10+L10+N10+P10+R10+T10+V10+X10+Z10+AB10+AD10+AF10 -> 45 | H10: 11 | I10: 0 | J10: 2 | K10: 0 | L10: 4 | M10: 0 | N10: 11 | O10: 0 | P10: 12 | Q10: 0 | R10: 2 | S10: 0 | T10: 1 | U10: 0 | V10: 0 | W10: 0 | X10: 0 | Y10: 0 | Z10: 0 | AA10: 0 | AB10: 0 | AC10: 0 | AD10: 2 | AE10: 0 | AF10: 0 | AG10: 0 | AH10: 10 | AI10: 35 | AJ10: 4866-5037-4983-5032-5034 | AK10: FIRMADO | AL10: NO | AM10: OK | AN10: BRAYAN ARDILA
E11: 9,10,11,12, | F11: 32 | G11: =+H11+J11+L11+N11+P11+R11+T11+V11+X11+Z11+AB11+AD11+AF11 -> 35 | H11: 7 | I11: 0 | J11: 2 | K11: 0 | L11: 0 | M11: 0 | N11: 8 | O11: 0 | P11: 15 | Q11: 0 | R11: 1 | S11: 0 | T11: 0 | U11: 0 | V11: 0 | W11: 0 | X11: 0 | Y11: 0 | Z11: 0 | AA11: 0 | AB11: 0 | AC11: 0 | AD11: 2 | AE11: 0 | AF11: 0 | AG11: 0 | AH11: 8 | AI11: 27 | AJ11: 5230-5231-5262-5232 | AK11: FIRMADO | AL11: NO | AM11: OK
E12: 16,17,18,19, | F12: 32 | G12: =+H12+J12+L12+N12+P12+R12+T12+V12+X12+Z12+AB12+AD12+AF12 -> 39 | H12: 1 | I12: 0 | J12: 2 | K12: 0 | L12: 0 | M12: 0 | N12: 18 | O12: 0 | P12: 9 | Q12: 0 | R12: 4 | S12: 0 | T12: 5 | U12: 0 | V12: 0 | W12: 0 | X12: 0 | Y12: 0 | Z12: 0 | AA12: 0 | AB12: 0 | AC12: 0 | AD12: 0 | AE12: 0 | AF12: 0 | AG12: 0 | AH12: 6 | AI12: 33 | AJ12: 5252-5253-5254-5286 | AK12: por firma de gestor | AL12: NO | AM12: OK
A14: Ips Comfandi El Prado | B14: =VLOOKUP(Tabla6[[#This Row],[SEDE]],'Cronog Junio 2026'!B5:C96,2,0) -> Bryan A. Urbano | C14: =VLOOKUP(Tabla6[[#This Row],[SEDE]],'Cronog Junio 2026'!B5:G96,6,0) -> SALUD | D14: =VLOOKUP(Tabla6[[#This Row],[SEDE]],'Cronog Junio 2026'!B5:D96,3,0) -> S010010205 | E14: 1,2,3,4,5,6, | F14: 48 | G14: =+H14+J14+L14+N14+P14+R14+T14+V14+X14+Z14+AB14+AD14+AF14 -> 35 | H14: 0 | I14: 0 | J14: 0 | K14: 0 | L14: 0 | M14: 0 | N14: 2 | O14: 0 | P14: 31 | Q14: 0 | R14: 0 | S14: 0 | T14: 0 | U14: 0 | V14: 0 | W14: 0 | X14: 2 | Y14: 0 | Z14: 0 | AA14: 0 | AB14: 0 | AC14: 0 | AD14: 0 | AE14: 0 | AF14: 0 | AG14: 0 | AH14: 13 | AI14: 22 | AJ14: 4921-4985-4986-4987-5076-5077 | AK14: por firma de gestor | AL14: NO | AM14: OK | AN14: ALBEIRO DURAN
E15: 9,10,11,12,13, | F15: 40 | G15: =+H15+J15+L15+N15+P15+R15+T15+V15+X15+Z15+AB15+AD15+AF15 -> 29 | H15: 0 | I15: 0 | J15: 0 | K15: 0 | L15: 0 | M15: 0 | N15: 7 | O15: 0 | P15: 20 | Q15: 0 | R15: 0 | S15: 0 | T15: 0 | U15: 0 | V15: 0 | W15: 0 | X15: 2 | Y15: 0 | Z15: 0 | AA15: 0 | AB15: 0 | AC15: 0 | AD15: 0 | AE15: 0 | AF15: 0 | AG15: 0 | AH15: 8 | AI15: 21 | AJ15: 5119-5177-5178-5179-5180 | AK15: por firma de gestor | AL15: NO | AM15: OK
A17: Centro Campestre Comfandi Arroyohondo | B17: =VLOOKUP(Tabla6[[#This Row],[SEDE]],'Cronog Junio 2026'!B6:C97,2,0) -> Hans Blake Salas Millan | C17: =VLOOKUP(Tabla6[[#This Row],[SEDE]],'Cronog Junio 2026'!B6:G97,6,0) -> RECREACION | D17: =VLOOKUP(Tabla6[[#This Row],[SEDE]],'Cronog Junio 2026'!B6:D97,3,0) -> R010210205 | E17: 1,2,3,4,5,6 | F17: 88 | G17: =+H17+J17+L17+N17+P17+R17+T17+V17+X17+Z17+AB17+AD17+AF17 -> 30 | H17: 11 | I17: 0 | J17: 4 | K17: 0 | L17: 10 | M17: 0 | N17: 0 | O17: 0 | P17: 0 | Q17: 0 | R17: 0 | S17: 0 | T17: 0 | U17: 0 | V17: 0 | W17: 0 | X17: 5 | Y17: 0 | Z17: 0 | AA17: 0 | AB17: 0 | AC17: 0 | AD17: 0 | AE17: 0 | AF17: 0 | AG17: 0 | AH17: 6 | AI17: 24 | AJ17: 5027-5036-5029-5035-5028-5044 | AK17: FIRMADO | AL17: NO | AM17: OK | AN17: HERNANDO NARVAEZ
E18: 9,10,11,12,13, | F18: 71 | G18: =+H18+J18+L18+N18+P18+R18+T18+V18+X18+Z18+AB18+AD18+AF18 -> 22 | H18: 5 | I18: 0 | J18: 4 | K18: 0 | L18: 13 | M18: 0 | N18: 0 | O18: 0 | P18: 0 | Q18: 0 | R18: 0 | S18: 0 | T18: 0 | U18: 0 | V18: 0 | W18: 0 | X18: 0 | Y18: 0 | Z18: 0 | AA18: 0 | AB18: 0 | AC18: 0 | AD18: 0 | AE18: 0 | AF18: 0 | AG18: 0 | AH18: 1 | AI18: 21 | AJ18: 5157-5158-5160-5161-5162 | AK18: FIRMADO | AL18: NO | AM18: OK
E19: 16,17,18,19,20, | F19: 72 | G19: =+H19+J19+L19+N19+P19+R19+T19+V19+X19+Z19+AB19+AD19+AF19 -> 18 | H19: 1 | I19: 0 | J19: 2 | K19: 0 | L19: 13 | M19: 0 | N19: 1 | O19: 0 | P19: 0 | Q19: 0 | R19: 0 | S19: 0 | T19: 1 | U19: 0 | V19: 0 | W19: 0 | X19: 0 | Y19: 0 | Z19: 0 | AA19: 0 | AB19: 0 | AC19: 0 | AD19: 0 | AE19: 0 | AF19: 0 | AG19: 0 | AH19: 10 | AI19: 8 | AJ19: 5310-5316--5319-5323-5324 | AK19: por firma de gestor | AL19: NO | AM19: OK
A21: Colegio Yumbo | B21: =VLOOKUP(Tabla6[[#This Row],[SEDE]],'Cronog Junio 2026'!B7:C98,2,0) -> Hans Blake Salas Millan | C21: =VLOOKUP(Tabla6[[#This Row],[SEDE]],'Cronog Junio 2026'!B7:G98,6,0) -> EDUCACION | D21: =VLOOKUP(Tabla6[[#This Row],[SEDE]],'Cronog Junio 2026'!B7:D98,3,0) -> E010030205 | E21: 1,2,3,4,5, | F21: 80 | G21: =+H21+J21+L21+N21+P21+R21+T21+V21+X21+Z21+AB21+AD21+AF21 -> 14 | H21: 0 | I21: 0 | J21: 0 | K21: 0 | L21: 2 | M21: 0 | N21: 2 | O21: 0 | P21: 1 | Q21: 0 | R21: 2 | S21: 0 | T21: 0 | U21: 0 | V21: 0 | W21: 0 | X21: 2 | Y21: 0 | Z21: 0 | AA21: 0 | AB21: 4 | AC21: 0 | AD21: 1 | AE21: 0 | AF21: 0 | AG21: 0 | AH21: 10 | AI21: 4 | AJ21: 4875-4933-4968-5006-5031 | AK21: FIRMADO | AL21: NO | AM21: OK | AN21: BRAYAN ARDILA
E22: 9,10,11,12,13 | F22: 72 | G22: =+H22+J22+L22+N22+P22+R22+T22+V22+X22+Z22+AB22+AD22+AF22 -> 19 | H22: 4 | I22: 0 | J22: 2 | K22: 0 | L22: 1 | M22: 0 | N22: 4 | O22: 0 | P22: 1 | Q22: 0 | R22: 1 | S22: 0 | T22: 0 | U22: 0 | V22: 0 | W22: 0 | X22: 2 | Y22: 0 | Z22: 0 | AA22: 0 | AB22: 4 | AC22: 0 | AD22: 0 | AE22: 0 | AF22: 0 | AG22: 0 | AH22: 7 | AI22: 12 | AJ22: 5075-5149-5159-5169-5167 | AK22: FIRMADO | AL22: NO | AM22: OK
E23: 16,17,18,19,20, | F23: 72.6 | G23: =+H23+J23+L23+N23+P23+R23+T23+V23+X23+Z23+AB23+AD23+AF23 -> 22 | H23: 3 | I23: 0 | J23: 1 | K23: 0 | L23: 3 | M23: 0 | N23: 9 | O23: 0 | P23: 0 | Q23: 0 | R23: 2 | S23: 0 | T23: 0 | U23: 0 | V23: 0 | W23: 0 | X23: 0 | Y23: 0 | Z23: 0 | AA23: 0 | AB23: 4 | AC23: 0 | AD23: 0 | AE23: 0 | AF23: 0 | AG23: 0 | AH23: 3 | AI23: 19 | AJ23: 5206-5335-5336-5341-5342 | AK23: por firma de gestor | AL23: NO | AM23: no
A25: Ips Comfandi Torres | B25: =VLOOKUP(Tabla6[[#This Row],[SEDE]],'Cronog Junio 2026'!B8:C99,2,0) -> Hans Blake Salas Millan | C25: =VLOOKUP(Tabla6[[#This Row],[SEDE]],'Cronog Junio 2026'!B8:G99,6,0) -> SALUD | D25: =VLOOKUP(Tabla6[[#This Row],[SEDE]],'Cronog Junio 2026'!B8:D99,3,0) -> S010140205 | E25: 1,2,3,4,5,6, | F25: 44 | G25: =+H25+J25+L25+N25+P25+R25+T25+V25+X25+Z25+AB25+AD25+AF25 -> 32 | H25: 0 | I25: 0 | J25: 0 | K25: 0 | L25: 17 | M25: 0 | N25: 1 | O25: 0 | P25: 9 | Q25: 0 | R25: 0 | S25: 0 | T25: 1 | U25: 0 | V25: 0 | W25: 0 | X25: 4 | Y25: 0 | Z25: 0 | AA25: 0 | AB25: 0 | AC25: 0 | AD25: 0 | AE25: 0 | AF25: 0 | AG25: 0 | AH25: 16 | AI25: 16 | AJ25: 4891-4980-4082-4984-5069-5084 | AK25: FIRMADO | AL25: NO | AM25: OK | AN25: ALBEIRO DURAN
E26: 9,10,11,12,13, | F26: 36 | G26: =+H26+J26+L26+N26+P26+R26+T26+V26+X26+Z26+AB26+AD26+AF26 -> 24 | H26: 1 | I26: 0 | J26: 1 | K26: 0 | L26: 13 | M26: 0 | N26: 2 | O26: 0 | P26: 6 | Q26: 0 | R26: 0 | S26: 0 | T26: 0 | U26: 0 | V26: 0 | W26: 0 | X26: 1 | Y26: 0 | Z26: 0 | AA26: 0 | AB26: 0 | AC26: 0 | AD26: 0 | AE26: 0 | AF26: 0 | AG26: 0 | AH26: 8 | AI26: 16 | AJ26: 5058-5101-5138-5140 | AK26: FIRMADO | AL26: NO | AM26: OK
E27: 16,17,18,19,20, | F27: 36 | G27: =+H27+J27+L27+N27+P27+R27+T27+V27+X27+Z27+AB27+AD27+AF27 -> 28 | H27: 1 | I27: 0 | J27: 2 | K27: 0 | L27: 17 | M27: 0 | N27: 0 | O27: 0 | P27: 8 | Q27: 0 | R27: 0 | S27: 0 | T27: 0 | U27: 0 | V27: 0 | W27: 0 | X27: 0 | Y27: 0 | Z27: 0 | AA27: 0 | AB27: 0 | AC27: 0 | AD27: 0 | AE27: 0 | AF27: 0 | AG27: 0 | AH27: 11 | AI27: 17 | AJ27: 5226-5227-5270-5283-5285 | AK27: FIRMADO | AL27: NO | AM27: OK
A28: Drogueria Av. 6 La Flora 2 | B28: =VLOOKUP(Tabla6[[#This Row],[SEDE]],'Cronog Junio 2026'!B9:C100,2,0) -> Hans Blake Salas Millan | C28: =VLOOKUP(Tabla6[[#This Row],[SEDE]],'Cronog Junio 2026'!B9:G100,6,0) -> MERCADEO | D28: =VLOOKUP(Tabla6[[#This Row],[SEDE]],'Cronog Junio 2026'!B9:D100,3,0) -> M012070213 | AN28: CESAR FRANCO
A29: Drogueria Av. Sexta | B29: =VLOOKUP(Tabla6[[#This Row],[SEDE]],'Cronog Junio 2026'!B10:C101,2,0) -> Hans Blake Salas Millan | C29: =VLOOKUP(Tabla6[[#This Row],[SEDE]],'Cronog Junio 2026'!B10:G101,6,0) -> MERCADEO | D29: =VLOOKUP(Tabla6[[#This Row],[SEDE]],'Cronog Junio 2026'!B10:D101,3,0) -> M010360213 | G29: =+H29+J29+L29+N29+P29+R29+T29+V29+X29+Z29+AB29+AD29+AF29 -> 0 | AN29: CESAR FRANCO
A30: Droguería Centenario | B30: =VLOOKUP(Tabla6[[#This Row],[SEDE]],'Cronog Junio 2026'!B11:C102,2,0) -> Bryan A. Urbano | C30: =VLOOKUP(Tabla6[[#This Row],[SEDE]],'Cronog Junio 2026'!B11:G102,6,0) -> MERCADEO | D30: =VLOOKUP(Tabla6[[#This Row],[SEDE]],'Cronog Junio 2026'!B11:D102,3,0) -> M011410213 | G30: =+H30+J30+L30+N30+P30+R30+T30+V30+X30+Z30+AB30+AD30+AF30 -> 0 | AN30: CESAR FRANCO
A31: Drogueria Chipichape | B31: =VLOOKUP(Tabla6[[#This Row],[SEDE]],'Cronog Junio 2026'!B12:C103,2,0) -> Hans Blake Salas Millan | C31: =VLOOKUP(Tabla6[[#This Row],[SEDE]],'Cronog Junio 2026'!B12:G103,6,0) -> MERCADEO | D31: =VLOOKUP(Tabla6[[#This Row],[SEDE]],'Cronog Junio 2026'!B12:D103,3,0) -> M011680213 | G31: =+H31+J31+L31+N31+P31+R31+T31+V31+X31+Z31+AB31+AD31+AF31 -> 0 | AN31: CESAR FRANCO
A32: Drogueria Clinica de Occidente | B32: =VLOOKUP(Tabla6[[#This Row],[SEDE]],'Cronog Junio 2026'!B13:C104,2,0) -> Bryan A. Urbano | C32: =VLOOKUP(Tabla6[[#This Row],[SEDE]],'Cronog Junio 2026'!B13:G104,6,0) -> MERCADEO | D32: =VLOOKUP(Tabla6[[#This Row],[SEDE]],'Cronog Junio 2026'!B13:D104,3,0) -> M011930213 | G32: =+H32+J32+L32+N32+P32+R32+T32+V32+X32+Z32+AB32+AD32+AF32 -> 0 | AN32: CESAR FRANCO
A33: Drogueria Clinica Remedios | B33: =VLOOKUP(Tabla6[[#This Row],[SEDE]],'Cronog Junio 2026'!B14:C105,2,0) -> Bryan A. Urbano | C33: =VLOOKUP(Tabla6[[#This Row],[SEDE]],'Cronog Junio 2026'!B14:G105,6,0) -> MERCADEO | D33: =VLOOKUP(Tabla6[[#This Row],[SEDE]],'Cronog Junio 2026'!B14:D105,3,0) -> M010410213 | G33: =+H33+J33+L33+N33+P33+R33+T33+V33+X33+Z33+AB33+AD33+AF33 -> 0 | AN33: CESAR FRANCO
A34: Drogueria El Prado | B34: =VLOOKUP(Tabla6[[#This Row],[SEDE]],'Cronog Junio 2026'!B15:C106,2,0) -> Bryan A. Urbano | C34: =VLOOKUP(Tabla6[[#This Row],[SEDE]],'Cronog Junio 2026'!B15:G106,6,0) -> MERCADEO | D34: =VLOOKUP(Tabla6[[#This Row],[SEDE]],'Cronog Junio 2026'!B15:D106,3,0) -> M010321701 | G34: =+H34+J34+L34+N34+P34+R34+T34+V34+X34+Z34+AB34+AD34+AF34 -> 0 | AN34: CESAR FRANCO
A35: Drogueria La Flora | B35: =VLOOKUP(Tabla6[[#This Row],[SEDE]],'Cronog Junio 2026'!B16:C107,2,0) -> Hans Blake Salas Millan | C35: =VLOOKUP(Tabla6[[#This Row],[SEDE]],'Cronog Junio 2026'!B16:G107,6,0) -> MERCADEO | D35: =VLOOKUP(Tabla6[[#This Row],[SEDE]],'Cronog Junio 2026'!B16:D107,3,0) -> M011080213 | G35: =+H35+J35+L35+N35+P35+R35+T35+V35+X35+Z35+AB35+AD35+AF35 -> 0 | AN35: CESAR FRANCO
A36: Ips Comfandi Yumbo | B36: =VLOOKUP(Tabla6[[#This Row],[SEDE]],'Cronog Junio 2026'!B17:C108,2,0) -> Hans Blake Salas Millan | C36: =VLOOKUP(Tabla6[[#This Row],[SEDE]],'Cronog Junio 2026'!B17:G108,6,0) -> SALUD | D36: =VLOOKUP(Tabla6[[#This Row],[SEDE]],'Cronog Junio 2026'!B17:D108,3,0) -> S010030205 | E36: 1,2,3,4,5,6,9,10,11, | F36: 136 | G36: =+H36+J36+L36+N36+P36+R36+T36+V36+X36+Z36+AB36+AD36+AF36 -> 38 | H36: 5 | I36: 0 | J36: 6 | K36: 0 | L36: 9 | M36: 0 | N36: 1 | O36: 0 | P36: 0 | Q36: 0 | R36: 4 | S36: 0 | T36: 1 | U36: 0 | V36: 1 | W36: 0 | X36: 11 | Y36: 0 | Z36: 0 | AA36: 0 | AB36: 0 | AC36: 0 | AD36: 0 | AE36: 0 | AF36: 0 | AG36: 0 | AH36: 23 | AI36: 15 | AJ36: 5046-5050-5051-5056-5057-5059-5098-5114-5117 | AK36: por firma de gestor | AL36: NO | AM36: OK | AN36: ALBEIRO DURAN
A37: Colegio Municipal | B37: =VLOOKUP(Tabla6[[#This Row],[SEDE]],'Cronog Junio 2026'!B18:C109,2,0) -> Bryan A. Urbano | C37: =VLOOKUP(Tabla6[[#This Row],[SEDE]],'Cronog Junio 2026'!B18:G109,6,0) -> EDUCACION | D37: =VLOOKUP(Tabla6[[#This Row],[SEDE]],'Cronog Junio 2026'!B18:D109,3,0) -> E010600205 | E37: 12,13,16,17,18,19,20, | F37: 96 | G37: 30 | H37: 3 | I37: 0 | J37: 8 | K37: 0 | L37: 6 | M37: 0 | N37: 2 | O37: 0 | P37: 1 | Q37: 0 | R37: 5 | S37: 0 | T37: 0 | U37: 0 | V37: 1 | W37: 0 | X37: 2 | Y37: 0 | Z37: 0 | AA37: 0 | AB37: 1 | AC37: 0 | AD37: 1 | AE37: 0 | AF37: 0 | AG37: 0 | AH37: 19 | AI37: 11 | AJ37: 5368-5370-5373-5383-5387-5389-5391 | AK37: por firma de gestor | AL37: NO | AM37: no | AN37: BRAYAN ARDILA
A38: Colegio Las Delicias | B38: =VLOOKUP(Tabla6[[#This Row],[SEDE]],'Cronog Junio 2026'!B19:C110,2,0) -> Bryan A. Urbano | C38: =VLOOKUP(Tabla6[[#This Row],[SEDE]],'Cronog Junio 2026'!B19:G110,6,0) -> EDUCACION | D38: =VLOOKUP(Tabla6[[#This Row],[SEDE]],'Cronog Junio 2026'!B19:D110,3,0) -> E010190205 | G38: =+H38+J38+L38+N38+P38+R38+T38+V38+X38+Z38+AB38+AD38+AF38 -> 0 | AN38: BRAYAN ARDILA
A39: Ips Comfandi Alameda | B39: =VLOOKUP(Tabla6[[#This Row],[SEDE]],'Cronog Junio 2026'!B20:C111,2,0) -> Bryan A. Urbano | C39: =VLOOKUP(Tabla6[[#This Row],[SEDE]],'Cronog Junio 2026'!B20:G111,6,0) -> SALUD | D39: =VLOOKUP(Tabla6[[#This Row],[SEDE]],'Cronog Junio 2026'!B20:D111,3,0) -> S010080205 | E39: 1,2,3,4,5,6,9,10,11, | F39: 136 | G39: 48 | H39: 11 | I39: 0 | J39: 8 | K39: 0 | L39: 6 | M39: 0 | N39: 3 | O39: 0 | P39: 1 | Q39: 0 | R39: 5 | S39: 0 | T39: 1 | U39: 0 | V39: 2 | W39: 0 | X39: 6 | Y39: 0 | Z39: 0 | AA39: 0 | AB39: 2 | AC39: 0 | AD39: 3 | AE39: 0 | AF39: 0 | AG39: 0 | AH39: 13 | AI39: 35 | AJ39: 4968-4922-4968-4988-5011-5013-5078-5102-5120 | AK39: por firma de gestor | AL39: NO | AM39: OK | AN39: ALBEIRO DURAN
A40: Colegio Miraflores Sede Bachillerato | B40: =VLOOKUP(Tabla6[[#This Row],[SEDE]],'Cronog Junio 2026'!B21:C112,2,0) -> Bryan A. Urbano | C40: =VLOOKUP(Tabla6[[#This Row],[SEDE]],'Cronog Junio 2026'!B21:G112,6,0) -> EDUCACION | D40: =VLOOKUP(Tabla6[[#This Row],[SEDE]],'Cronog Junio 2026'!B21:D112,3,0) -> E010620205 | G40: =+H40+J40+L40+N40+P40+R40+T40+V40+X40+Z40+AB40+AD40+AF40 -> 0 | AN40: BRAYAN ARDILA
A41: Campus E Centro | B41: =VLOOKUP(Tabla6[[#This Row],[SEDE]],'Cronog Junio 2026'!B22:C113,2,0) -> Bryan A. Urbano | C41: =VLOOKUP(Tabla6[[#This Row],[SEDE]],'Cronog Junio 2026'!B22:G113,6,0) -> EDUCACION | D41: =VLOOKUP(Tabla6[[#This Row],[SEDE]],'Cronog Junio 2026'!B22:D113,3,0) -> E010050205 | E41: 1,2,3,4,5,6,9,10,11, | F41: 136 | G41: 39 | H41: 8 | I41: 0 | J41: 8 | K41: 0 | L41: 5 | M41: 0 | N41: 6 | O41: 0 | P41: 2 | Q41: 0 | R41: 4 | S41: 0 | T41: 1 | U41: 0 | V41: 1 | W41: 0 | X41: 3 | Y41: 0 | Z41: 0 | AA41: 0 | AB41: 1 | AC41: 0 | AD41: 0 | AE41: 0 | AF41: 0 | AG41: 0 | AH41: 16 | AI41: 23 | AJ41: 4936-4955-49814-5005-5112-5113-5259-5260-5261 | AK41: por firma de gestor | AL41: NO | AM41: OK | AN41: BRAYAN ARDILA
A42: Campus E Centro (Fomento Piso 3) | B42: =VLOOKUP(Tabla6[[#This Row],[SEDE]],'Cronog Junio 2026'!B23:C114,2,0) -> Bryan A. Urbano | C42: =VLOOKUP(Tabla6[[#This Row],[SEDE]],'Cronog Junio 2026'!B23:G114,6,0) -> EDUCACION | D42: =VLOOKUP(Tabla6[[#This Row],[SEDE]],'Cronog Junio 2026'!B23:D114,3,0) -> E010050205 | E42: 12;13, | F42: 24 | G42: 5 | H42: 0 | I42: 0 | J42: 0 | K42: 0 | L42: 0 | M42: 0 | N42: 0 | O42: 0 | P42: 1 | Q42: 0 | R42: 0 | S42: 0 | T42: 1 | U42: 0 | V42: 0 | W42: 0 | X42: 3 | Y42: 0 | Z42: 0 | AA42: 0 | AB42: 0 | AC42: 0 | AD42: 0 | AE42: 0 | AF42: 0 | AG42: 0 | AH42: 4 | AI42: 1 | AJ42: 5262-5263 | AK42: por firma de gestor | AL42: NO | AM42: no | AN42: BRAYAN ARDILA
A43: Colegio Calipso | B43: =VLOOKUP(Tabla6[[#This Row],[SEDE]],'Cronog Junio 2026'!B24:C115,2,0) -> Bryan A. Urbano | C43: =VLOOKUP(Tabla6[[#This Row],[SEDE]],'Cronog Junio 2026'!B24:G115,6,0) -> EDUCACION | D43: =VLOOKUP(Tabla6[[#This Row],[SEDE]],'Cronog Junio 2026'!B24:D115,3,0) -> E010020205 | E43: 16,17,18,19,20,22, | F43: 88 | G43: =+H43+J43+L43+N43+P43+R43+T43+V43+X43+Z43+AB43+AD43+AF43 -> 29 | H43: 3 | I43: 0 | J43: 4 | K43: 0 | L43: 5 | M43: 0 | N43: 0 | O43: 0 | P43: 3 | Q43: 0 | R43: 10 | S43: 0 | T43: 0 | U43: 0 | V43: 1 | W43: 0 | X43: 2 | Y43: 0 | Z43: 0 | AA43: 0 | AB43: 1 | AC43: 0 | AD43: 0 | AE43: 0 | AF43: 0 | AG43: 0 | AH43: 14 | AI43: 15 | AJ43: 5266-5267-5269-5273-5327-5329 | AK43: por firma de gestor | AL43: NO | AM43: no | AN43: BRAYAN ARDILA
A44: Colegio San Nicolas - Biblioteca - Auditorio | B44: =VLOOKUP(Tabla6[[#This Row],[SEDE]],'Cronog Junio 2026'!B25:C116,2,0) -> Bryan A. Urbano | C44: =VLOOKUP(Tabla6[[#This Row],[SEDE]],'Cronog Junio 2026'!B25:G116,6,0) -> EDUCACION | D44: =VLOOKUP(Tabla6[[#This Row],[SEDE]],'Cronog Junio 2026'!B25:D116,3,0) -> E010040205 | E44: 1,2,3,4,5,6,9,10,11, | F44: 136 | G44: =+H44+J44+L44+N44+P44+R44+T44+V44+X44+Z44+AB44+AD44+AF44 -> 55 | H44: 6 | I44: 0 | J44: 4 | K44: 0 | L44: 4 | M44: 0 | N44: 3 | O44: 0 | P44: 0 | Q44: 0 | R44: 9 | S44: 0 | T44: 3 | U44: 0 | V44: 8 | W44: 0 | X44: 5 | Y44: 0 | Z44: 3 | AA44: 0 | AB44: 8 | AC44: 0 | AD44: 2 | AE44: 0 | AF44: 0 | AG44: 0 | AH44: 25 | AI44: 30 | AJ44: 5174-5175-5191-5203-5213-5216-5218-5220-5221 | AK44: por firma de gestor | AL44: NO | AM44: no | AN44: BRAYAN ARDILA
A45: Ips Comfandi San Nicolas | B45: =VLOOKUP(Tabla6[[#This Row],[SEDE]],'Cronog Junio 2026'!B26:C117,2,0) -> Bryan A. Urbano | C45: =VLOOKUP(Tabla6[[#This Row],[SEDE]],'Cronog Junio 2026'!B26:G117,6,0) -> SALUD | D45: =VLOOKUP(Tabla6[[#This Row],[SEDE]],'Cronog Junio 2026'!B26:D117,3,0) -> S010160205 | G45: =+H45+J45+L45+N45+P45+R45+T45+V45+X45+Z45+AB45+AD45+AF45 -> 0 | AN45: ALBEIRO DURAN
A46: IETDH San Nicolas | B46: =VLOOKUP(Tabla6[[#This Row],[SEDE]],'Cronog Junio 2026'!B27:C118,2,0) -> Bryan A. Urbano | C46: =VLOOKUP(Tabla6[[#This Row],[SEDE]],'Cronog Junio 2026'!B27:G118,6,0) -> EDUCACION | D46: =VLOOKUP(Tabla6[[#This Row],[SEDE]],'Cronog Junio 2026'!B27:D118,3,0) -> E010046105 | E46: 12,13,16,17,18,19,20,22,23,24, | F46: 144 | G46: =+H46+J46+L46+N46+P46+R46+T46+V46+X46+Z46+AB46+AD46+AF46 -> 58 | H46: 7 | I46: 0 | J46: 17 | K46: 0 | L46: 12 | M46: 0 | N46: 0 | O46: 0 | P46: 1 | Q46: 0 | R46: 5 | S46: 0 | T46: 4 | U46: 0 | V46: 2 | W46: 0 | X46: 3 | Y46: 0 | Z46: 0 | AA46: 0 | AB46: 6 | AC46: 0 | AD46: 1 | AE46: 0 | AF46: 0 | AG46: 0 | AH46: 27 | AI46: 31 | AJ46: 5339-4343-4371-5372-5374-5375-5385-5386-5388-5390 | AK46: por firma de gestor | AL46: NO | AM46: no | AN46: BRAYAN ARDILA
A47: Colegio El Prado Sede Bachillerato (Móvil) | B47: =VLOOKUP(Tabla6[[#This Row],[SEDE]],'Cronog Junio 2026'!B28:C119,2,0) -> Bryan A. Urbano | C47: =VLOOKUP(Tabla6[[#This Row],[SEDE]],'Cronog Junio 2026'!B28:G119,6,0) -> EDUCACION | D47: =VLOOKUP(Tabla6[[#This Row],[SEDE]],'Cronog Junio 2026'!B28:D119,3,0) -> E010010205 | G47: =+H47+J47+L47+N47+P47+R47+T47+V47+X47+Z47+AB47+AD47+AF47 -> 0 | AN47: BRAYAN ARDILA
...

Sheet Datos
B1: 1 | D1: 2 | F1: 3 | H1: 4 | J1: 5 | L1: 6 | N1: 7 | P1: 8 | R1: 9 | T1: 10 | V1: 11 | X1: 12 | Z1: 13
B2: HID-SAN | C2: Tipo | D2: INS-ELE | E2: M2 | F2: OBR-CIV | G2: M2 | H2: APY-LOG | I2: Horas | J2: APY-MTTO | K2: Horas | L2: CARP-MET | M2: Tipo | N2: CHA-LLAV | O2: Tipo | P2: CARP-MAD | Q2: Tipo | R2: PINT | S2: M2 | T2: ADE-OFI | U2: Tipo | V2: CUBI | W2: M2 | X2: SEÑA | Y2: Tipo | Z2: PERSIA | AA2: Tipo | AB2: Total | AD2: CON COBRO | AE2: SIN COBRO
A3: 1 | F3: 1 | AB3: =B3+D3+F3+H3+L3+N3+P3+R3+T3+V3+X3+Z3+J3 -> 1 | AD3: 1 | AE3: 0 | AF3: =SUM(AD3:AE3) -> 1
A4: 2 | F4: 1 | AB4: =B4+D4+F4+H4+L4+N4+P4+R4+T4+V4+X4+Z4+J4 -> 1 | AD4: 1 | AE4: 0 | AF4: =SUM(AD4:AE4) -> 1
A5: 3 | B5: 1 | F5: 1 | AB5: =B5+D5+F5+H5+L5+N5+P5+R5+T5+V5+X5+Z5+J5 -> 2 | AD5: 1 | AE5: 1 | AF5: =SUM(AD5:AE5) -> 2
A6: 4 | L6: 1 | R6: 1 | AB6: =B6+D6+F6+H6+L6+N6+P6+R6+T6+V6+X6+Z6+J6 -> 2 | AD6: 2 | AE6: 0 | AF6: =SUM(AD6:AE6) -> 2
A7: 5 | N7: 1 | R7: 1 | V7: 6 | AB7: =B7+D7+F7+H7+L7+N7+P7+R7+T7+V7+X7+Z7+J7 -> 8 | AD7: 1 | AE7: 7 | AF7: =SUM(AD7:AE7) -> 8
A8: 6 | AB8: =B8+D8+F8+H8+L8+N8+P8+R8+T8+V8+X8+Z8+J8 -> 0 | AF8: =SUM(AD8:AE8) -> 0
A9: 7 | AB9: =B9+D9+F9+H9+L9+N9+P9+R9+T9+V9+X9+Z9+J9 -> 0 | AF9: =SUM(AD9:AE9) -> 0
A10: 8 | AB10: =B10+D10+F10+H10+L10+N10+P10+R10+T10+V10+X10+Z10+J10 -> 0 | AF10: =SUM(AD10:AE10) -> 0
A11: 9 | AB11: =B11+D11+F11+H11+L11+N11+P11+R11+T11+V11+X11+Z11+J11 -> 0 | AF11: =SUM(AD11:AE11) -> 0
A12: 10 | AB12: =B12+D12+F12+H12+L12+N12+P12+R12+T12+V12+X12+Z12+J12 -> 0 | AF12: =SUM(AD12:AE12) -> 0
A13: 11 | AB13: =B13+D13+F13+H13+L13+N13+P13+R13+T13+V13+X13+Z13+J13 -> 0 | AF13: =SUM(AD13:AE13) -> 0
A14: 12 | AB14: =B14+D14+F14+H14+L14+N14+P14+R14+T14+V14+X14+Z14+J14 -> 0 | AF14: =SUM(AD14:AE14) -> 0
A15: 13 | AB15: =B15+D15+F15+H15+L15+N15+P15+R15+T15+V15+X15+Z15+J15 -> 0 | AF15: =SUM(AD15:AE15) -> 0
A16: 14 | AB16: =B16+D16+F16+H16+L16+N16+P16+R16+T16+V16+X16+Z16+J16 -> 0 | AF16: =SUM(AD16:AE16) -> 0
A17: 15 | AB17: =B17+D17+F17+H17+L17+N17+P17+R17+T17+V17+X17+Z17+J17 -> 0 | AF17: =SUM(AD17:AE17) -> 0
A18: 16 | AB18: =B18+D18+F18+H18+L18+N18+P18+R18+T18+V18+X18+Z18+J18 -> 0 | AF18: =SUM(AD18:AE18) -> 0
A19: 17 | AB19: =B19+D19+F19+H19+L19+N19+P19+R19+T19+V19+X19+Z19+J19 -> 0 | AF19: =SUM(AD19:AE19) -> 0
B20: =SUM(B3:B19) -> 1 | C20: =SUM(C3:C19) -> 0 | D20: =SUM(D3:D19) -> 0 | E20: =SUM(E3:E19) -> 0 | F20: =SUM(F3:F19) -> 3 | G20: =SUM(G3:G19) -> 0 | H20: =SUM(H3:H19) -> 0 | I20: =SUM(I3:I19) -> 0 | ... AA20: =SUM(AA3:AA19) -> 0 | AB20: Suma Parcial | AD20: =SUM(AD3:AD19) -> 6 | AE20: =SUM(AE3:AE19) -> 8
B21: =+B20+D20+F20+H20+L20+N20+P20+R20+T20+V20+X20+Z20+J20 -> 14 | AB21: Suma Total | AD21: =+AD20+AE20 -> 14
B24: 1 | D24: HID-SAN | F24: Mtto y Reparación Hidro-Sanitario
B25: 2 | D25: INS-ELE | F25: Mtto y Reparación Instalaciones Electricas
B26: 3 | D26: OBR-CIV | F26: Mtto y Reparación Obra Civil
B27: 4 | D27: APY-LOG | F27: Apoyo Logistico
B28: 5 | D28: APY-MTTO | F28: Temas de Rutina de mantenimiento preventivo
B29: 6 | D29: CARP-MET | F29: Mtto y Reparacion Carpinteria Metalica
B30: 7 | D30: CHA-LLAV | F30: Mtto y Reparacion Chapas y Llaves
B31: 8 | D31: CARP-MAD | F31: Mtto y Reparacion Carpinteria Madera
B32: 9 | D32: PINT | F32: Mtto Pinturas
B33: 10 | D33: ADE-OFI | F33: Adecuacion Oficina
B34: 11 | D34: CUBI | F34: Mtto y Reparacion Cubiertas
B35: 12 | D35: SEÑA | F35: Señalización
B36: 13 | D36: PERSIA | F36: Mtto y Reparacion Persiana

Sheet Consolidado Entregas
A1: CONSOLIDADO RELACIONES DE ENTREGA MANTENIMIENTO PROGRAMADO
J2: CANTIDAD AUTOGESTIONES-PILARES DE MANTENIMIENTO
A3: N° ENTREGA | B3: FECHA DILIGENC. | C3: SEDE | D3: SUPERVISOR RESPONSABLE | E3: UES | F3: C. COSTO | G3: FECHAS DE EJECUCIÓN | H3: HORAS EJECUTADAS | I3: Q AUTOGEST. | J3: HID-SAN | K3: INS-ELE | L3: OBR-CIV | M3: APY-LOG | N3: APY-MTTO | O3: CARP-MET | P3: CHA-LLAV | Q3: CARP-MAD | R3: PINT | S3: ADE-OFI | T3: CUBI | U3: SEÑA | V3: PERSIA | W3: CON COBRO | X3: SIN COBRO | Y3: N° CHECK LIST
A7: Total | C7: =SUBTOTAL(103,Tabla7[SEDE]) -> 0 | H7: =SUBTOTAL(109,Tabla7[HORAS EJECUTADAS]) -> 0 | I7: =SUBTOTAL(109,Tabla7[Q AUTOGEST.]) -> 0 | J7: =SUBTOTAL(109,Tabla7[HID-SAN]) -> 0 | K7: =SUBTOTAL(109,Tabla7[INS-ELE]) -> 0 | L7: =SUBTOTAL(109,Tabla7[OBR-CIV]) -> 0 | M7: =SUBTOTAL(109,Tabla7[APY-LOG]) -> 0 | N7: =SUBTOTAL(109,Tabla7[APY-MTTO]) -> 0 | O7: =SUBTOTAL(109,Tabla7[CARP-MET]) -> 0 | P7: =SUBTOTAL(109,Tabla7[CHA-LLAV]) -> 0 | Q7: =SUBTOTAL(109,Tabla7[CARP-MAD]) -> 0 | R7: =SUBTOTAL(109,Tabla7[PINT]) -> 0 | S7: =SUBTOTAL(109,Tabla7[ADE-OFI]) -> 0 | T7: =SUBTOTAL(109,Tabla7[CUBI]) -> 0 | U7: =SUBTOTAL(109,Tabla7[SEÑA]) -> 0 | V7: =SUBTOTAL(109,Tabla7[PERSIA]) -> 0 | W7: =SUBTOTAL(109,Tabla7[CON COBRO]) -> 0 | X7: =SUBTOTAL(109,Tabla7[SIN COBRO]) -> 0

Sheet SEGUIMIENTO
A1: VA EN EL ADJUNTO | F1: DIRIGIDO A: | H1: CON COPIA A:
A3: sabado, 13 de junio 2026 | B3: Ciudad | C3: UES | D3: Supervisor a Cargo | E3: Facilitador Comfandi | F3: Correo Sede | G3: Correo Facilitador | H3: CORREO UES | I3: SEGURIDAD CORPORATIVA | J3: CORREOS A NIVEL CENTRAL | K3: CORREOS BRILLASEO
B4: =VLOOKUP(Tabla425[[#This Row],[sabado, 13 de junio 2026]],'Cronog Junio 2026'!B:AT,4,0) -> #N/A | C4: =VLOOKUP(Tabla425[[#This Row],[sabado, 13 de junio 2026]],'Cronog Junio 2026'!B:AT,6,0) -> #N/A | D4: =VLOOKUP(Tabla425[[#This Row],[sabado, 13 de junio 2026]],'Cronog Junio 2026'!B:AT,2,0) -> #N/A | E4: Jairo Arboleda | F4: =VLOOKUP(Tabla425[[#This Row],[sabado, 13 de junio 2026]],'CORREOS 01'!A:B,2,0) -> #N/A | G4: =VLOOKUP(Tabla425[[#This Row],[Facilitador Comfandi]],#REF!,2,0) -> #REF! | H4: =IFERROR(VLOOKUP(Tabla425[[#This Row],[UES]],'Directorio Infraestructura'!$A$37:$D$41,4,0),"") | I4: =IF(Tabla425[[#This Row],[Ciudad]]="Cali",'Directorio Infraestructura'!$B$31,'Directorio Infraestructura'!$B$32) -> #N/A | J4: ='Directorio Infraestructura'!$B$48 -> francygaleano@comfandi.com.co; viviansramirez@comfandi.com.co; jansengiraldo@comfandi.com.co; brayanardila@comfandi.com.co; leonardosarria@comfandi.com.co; aprendizmantenimiento1@comfandi.com.co;sebastianarias@comfandi.com.co;hectorcaicedo@comfandi.com.co; mariamartinez@comfandi.com.co; yubizanvelasco@comfandi.com.co | K4: ='Directorio Infraestructura'!$B$49 -> analista1sst.comfandi@brillaseo.com; jhaidy.ruiz@brillaseo.com; almacen1.comfandi@brillaseo.com; alejandro.marin@brillaseo.co;andres.ramirez@brillaseo.co;bryan.martinez@brillaseo.co;adrian.restrepo@brillaseo.co
B5: =VLOOKUP(Tabla425[[#This Row],[sabado, 13 de junio 2026]],'Cronog Junio 2026'!B:AT,4,0) -> #N/A | C5: =VLOOKUP(Tabla425[[#This Row],[sabado, 13 de junio 2026]],'Cronog Junio 2026'!B:AT,6,0) -> #N/A | D5: =VLOOKUP(Tabla425[[#This Row],[sabado, 13 de junio 2026]],'Cronog Junio 2026'!B:AT,2,0) -> #N/A | E5: =VLOOKUP(Tabla425[[#This Row],[sabado, 13 de junio 2026]],#REF!,10,0) -> #REF! | F5: =VLOOKUP(Tabla425[[#This Row],[sabado, 13 de junio 2026]],'CORREOS 01'!A:B,2,0) -> #N/A | G5: =VLOOKUP(Tabla425[[#This Row],[Facilitador Comfandi]],#REF!,2,0) -> #REF! | H5: =IFERROR(VLOOKUP(Tabla425[[#This Row],[UES]],'Directorio Infraestructura'!$A$37:$D$41,4,0),"") | I5: =IF(Tabla425[[#This Row],[Ciudad]]="Cali",'Directorio Infraestructura'!$B$31,'Directorio Infraestructura'!$B$32) -> #N/A
B6: =VLOOKUP(Tabla425[[#This Row],[sabado, 13 de junio 2026]],'Cronog Junio 2026'!B:AT,4,0) -> #N/A | C6: =VLOOKUP(Tabla425[[#This Row],[sabado, 13 de junio 2026]],'Cronog Junio 2026'!B:AT,6,0) -> #N/A | D6: =VLOOKUP(Tabla425[[#This Row],[sabado, 13 de junio 2026]],'Cronog Junio 2026'!B:AT,2,0) -> #N/A | E6: =VLOOKUP(Tabla425[[#This Row],[sabado, 13 de junio 2026]],#REF!,10,0) -> #REF! | F6: =VLOOKUP(Tabla425[[#This Row],[sabado, 13 de junio 2026]],'CORREOS 01'!A:B,2,0) -> #N/A | G6: =VLOOKUP(Tabla425[[#This Row],[Facilitador Comfandi]],#REF!,2,0) -> #REF! | H6: =IFERROR(VLOOKUP(Tabla425[[#This Row],[UES]],'Directorio Infraestructura'!$A$37:$D$41,4,0),"") | I6: =IF(Tabla425[[#This Row],[Ciudad]]="Cali",'Directorio Infraestructura'!$B$31,'Directorio Infraestructura'!$B$32) -> #N/A
B7: =VLOOKUP(Tabla425[[#This Row],[sabado, 13 de junio 2026]],'Cronog Junio 2026'!B:AT,4,0) -> #N/A | C7: =VLOOKUP(Tabla425[[#This Row],[sabado, 13 de junio 2026]],'Cronog Junio 2026'!B:AT,6,0) -> #N/A | D7: =VLOOKUP(Tabla425[[#This Row],[sabado, 13 de junio 2026]],'Cronog Junio 2026'!B:AT,2,0) -> #N/A | E7: =VLOOKUP(Tabla425[[#This Row],[sabado, 13 de junio 2026]],#REF!,10,0) -> #REF! | F7: =VLOOKUP(Tabla425[[#This Row],[sabado, 13 de junio 2026]],'CORREOS 01'!A:B,2,0) -> #N/A | G7: =VLOOKUP(Tabla425[[#This Row],[Facilitador Comfandi]],#REF!,2,0) -> #REF! | H7: =IFERROR(VLOOKUP(Tabla425[[#This Row],[UES]],'Directorio Infraestructura'!$A$37:$D$41,4,0),"") | I7: =IF(Tabla425[[#This Row],[Ciudad]]="Cali",'Directorio Infraestructura'!$B$31,'Directorio Infraestructura'!$B$32) -> #N/A
B8: =VLOOKUP(Tabla425[[#This Row],[sabado, 13 de junio 2026]],'Cronog Junio 2026'!B:AT,4,0) -> #N/A | C8: =VLOOKUP(Tabla425[[#This Row],[sabado, 13 de junio 2026]],'Cronog Junio 2026'!B:AT,6,0) -> #N/A | D8: =VLOOKUP(Tabla425[[#This Row],[sabado, 13 de junio 2026]],'Cronog Junio 2026'!B:AT,2,0) -> #N/A | E8: =VLOOKUP(Tabla425[[#This Row],[sabado, 13 de junio 2026]],#REF!,10,0) -> #REF! | F8: =VLOOKUP(Tabla425[[#This Row],[sabado, 13 de junio 2026]],'CORREOS 01'!A:B,2,0) -> #N/A | G8: =VLOOKUP(Tabla425[[#This Row],[Facilitador Comfandi]],#REF!,2,0) -> #REF! | H8: =IFERROR(VLOOKUP(Tabla425[[#This Row],[UES]],'Directorio Infraestructura'!$A$37:$D$41,4,0),"") | I8: =IF(Tabla425[[#This Row],[Ciudad]]="Cali",'Directorio Infraestructura'!$B$31,'Directorio Infraestructura'!$B$32) -> #N/A
B9: =VLOOKUP(Tabla425[[#This Row],[sabado, 13 de junio 2026]],'Cronog Junio 2026'!B:AT,4,0) -> #N/A | C9: =VLOOKUP(Tabla425[[#This Row],[sabado, 13 de junio 2026]],'Cronog Junio 2026'!B:AT,6,0) -> #N/A | D9: =VLOOKUP(Tabla425[[#This Row],[sabado, 13 de junio 2026]],'Cronog Junio 2026'!B:AT,2,0) -> #N/A | E9: =VLOOKUP(Tabla425[[#This Row],[sabado, 13 de junio 2026]],#REF!,10,0) -> #REF! | F9: =VLOOKUP(Tabla425[[#This Row],[sabado, 13 de junio 2026]],'CORREOS 01'!A:B,2,0) -> #N/A | G9: =VLOOKUP(Tabla425[[#This Row],[Facilitador Comfandi]],#REF!,2,0) -> #REF! | H9: =IFERROR(VLOOKUP(Tabla425[[#This Row],[UES]],'Directorio Infraestructura'!$A$37:$D$41,4,0),"") | I9: =IF(Tabla425[[#This Row],[Ciudad]]="Cali",'Directorio Infraestructura'!$B$31,'Directorio Infraestructura'!$B$32) -> #N/A
B10: =VLOOKUP(Tabla425[[#This Row],[sabado, 13 de junio 2026]],'Cronog Junio 2026'!B:AT,4,0) -> #N/A | C10: =VLOOKUP(Tabla425[[#This Row],[sabado, 13 de junio 2026]],'Cronog Junio 2026'!B:AT,6,0) -> #N/A | D10: =VLOOKUP(Tabla425[[#This Row],[sabado, 13 de junio 2026]],'Cronog Junio 2026'!B:AT,2,0) -> #N/A | E10: =VLOOKUP(Tabla425[[#This Row],[sabado, 13 de junio 2026]],#REF!,10,0) -> #REF! | F10: =VLOOKUP(Tabla425[[#This Row],[sabado, 13 de junio 2026]],'CORREOS 01'!A:B,2,0) -> #N/A | G10: =VLOOKUP(Tabla425[[#This Row],[Facilitador Comfandi]],#REF!,2,0) -> #REF! | H10: =IFERROR(VLOOKUP(Tabla425[[#This Row],[UES]],'Directorio Infraestructura'!$A$37:$D$41,4,0),"") | I10: =IF(Tabla425[[#This Row],[Ciudad]]="Cali",'Directorio Infraestructura'!$B$31,'Directorio Infraestructura'!$B$32) -> #N/A
